Workbook
Name Slicer_Region: #N/A
Name Slicer_Segment: #N/A
Name Slicer_Year: #N/A

Sheet Data
A1: Customer Name | B1: Order ID | C1: Year | D1: Order Date | E1: Ship Date | F1: Ship Mode | G1: Customer ID | H1: Segment | I1: Country | J1: City | K1: State | L1: Postal Code | M1: Region | N1: Product ID | O1: Category | P1: Sub-Category | Q1: Sales | R1: Quantity | S1: Discount | T1: Profit
A2: Claire Gute | B2: CA-2013-152156 | C2: =YEAR(Data!$D2) -> 2013 | D2: 41587 | E2: 41590 | F2: Second Class | G2: CG-12520 | H2: Consumer | I2: United States | J2: Henderson | K2: Kentucky | L2: 42420 | M2: South | N2: FUR-BO-10001798 | O2: Furniture | P2: Bookcases | Q2: 261.96 | R2: 2 | S2: 0 | T2: 41.9136
A3: Darrin Van Huff | B3: CA-2013-138688 | C3: =YEAR(Data!$D4) -> 2012 | D3: 41438 | E3: 41442 | F3: Second Class | G3: DV-13045 | H3: Corporate | I3: United States | J3: Los Angeles | K3: California | L3: 90036 | M3: West | N3: OFF-LA-10000240 | O3: Office Supplies | P3: Labels | Q3: 14.62 | R3: 2 | S3: 0 | T3: 6.8714
A4: Sean O'Donnell | B4: US-2012-108966 | C4: =YEAR(Data!$D5) -> 2011 | D4: 41193 | E4: 41200 | F4: Standard Class | G4: SO-20335 | H4: Consumer | I4: United States | J4: Fort Lauderdale | K4: Florida | L4: 33311 | M4: South | N4: FUR-TA-10000577 | O4: Furniture | P4: Tables | Q4: 957.5775 | R4: 5 | S4: 0.45 | T4: -383.031
A5: Brosina Hoffman | B5: CA-2011-115812 | C5: =YEAR(Data!$D7) -> 2013 | D5: 40703 | E5: 40708 | F5: Standard Class | G5: BH-11710 | H5: Consumer | I5: United States | J5: Los Angeles | K5: California | L5: 90032 | M5: West | N5: FUR-FU-10001487 | O5: Furniture | P5: Furnishings | Q5: 48.86 | R5: 7 | S5: 0 | T5: 14.1694
A6: Andrew Allen | B6: CA-2014-114412 | C6: =YEAR(Data!$D14) -> 2012 | D6: 41745 | E6: 41750 | F6: Standard Class | G6: AA-10480 | H6: Consumer | I6: United States | J6: Concord | K6: North Carolina | L6: 28027 | M6: South | N6: OFF-PA-10002365 | O6: Office Supplies | P6: Paper | Q6: 15.552 | R6: 3 | S6: 0.2 | T6: 5.4432
A7: Irene Maddox | B7: CA-2013-161389 | C7: =YEAR(Data!$D15) -> 2013 | D7: 41614 | E7: 41619 | F7: Standard Class | G7: IM-15070 | H7: Consumer | I7: United States | J7: Seattle | K7: Washington | L7: 98103 | M7: West | N7: OFF-BI-10003656 | O7: Office Supplies | P7: Binders | Q7: 407.976 | R7: 3 | S7: 0.2 | T7: 132.5922
A8: Harold Pawlan | B8: US-2012-118983 | C8: =YEAR(Data!$D16) -> 2012 | D8: 41235 | E8: 41239 | F8: Standard Class | G8: HP-14815 | H8: Home Office | I8: United States | J8: Fort Worth | K8: Texas | L8: 76106 | M8: Central | N8: OFF-AP-10002311 | O8: Office Supplies | P8: Appliances | Q8: 68.81 | R8: 5 | S8: 0.8 | T8: -123.858
A9: Pete Kriz | B9: CA-2011-105893 | C9: =YEAR(Data!$D18) -> 2013 | D9: 40858 | E9: 40865 | F9: Standard Class | G9: PK-19075 | H9: Consumer | I9: United States | J9: Madison | K9: Wisconsin | L9: 53711 | M9: Central | N9: OFF-ST-10004186 | O9: Office Supplies | P9: Storage | Q9: 665.88 | R9: 6 | S9: 0 | T9: 13.3176
A10: Alejandro Grove | B10: CA-2011-167164 | C10: =YEAR(Data!$D19) -> 2012 | D10: 40676 | E10: 40678 | F10: Second Class | G10: AG-10270 | H10: Consumer | I10: United States | J10: West Jordan | K10: Utah | L10: 84084 | M10: West | N10: OFF-ST-10000107 | O10: Office Supplies | P10: Storage | Q10: 55.5 | R10: 2 | S10: 0 | T10: 9.99
A11: Zuschuss Donatelli | B11: CA-2011-143336 | C11: =YEAR(Data!$D20) -> 2014 | D11: 40782 | E11: 40787 | F11: Second Class | G11: ZD-21925 | H11: Consumer | I11: United States | J11: San Francisco | K11: California | L11: 94109 | M11: West | N11: OFF-AR-10003056 | O11: Office Supplies | P11: Art | Q11: 8.56 | R11: 2 | S11: 0 | T11: 2.4824
A12: Ken Black | B12: CA-2013-137330 | C12: =YEAR(Data!$D23) -> 2013 | D12: 41618 | E12: 41622 | F12: Standard Class | G12: KB-16585 | H12: Corporate | I12: United States | J12: Fremont | K12: Nebraska | L12: 68025 | M12: Central | N12: OFF-AR-10000246 | O12: Office Supplies | P12: Art | Q12: 19.46 | R12: 7 | S12: 0 | T12: 5.0596
A13: Sandra Flanagan | B13: US-2014-156909 | C13: =YEAR(Data!$D25) -> 2013 | D13: 41837 | E13: 41839 | F13: Second Class | G13: SF-20065 | H13: Consumer | I13: United States | J13: Philadelphia | K13: Pennsylvania | L13: 19140 | M13: East | N13: FUR-CH-10002774 | O13: Furniture | P13: Chairs | Q13: 71.372 | R13: 2 | S13: 0.3 | T13: -1.0196
A14: Emily Burns | B14: CA-2012-106320 | C14: =YEAR(Data!$D26) -> 2012 | D14: 41177 | E14: 41182 | F14: Standard Class | G14: EB-13870 | H14: Consumer | I14: United States | J14: Orem | K14: Utah | L14: 84057 | M14: West | N14: FUR-TA-10000577 | O14: Furniture | P14: Tables | Q14: 1044.63 | R14: 3 | S14: 0 | T14: 240.2649
A15: Eric Hoffmann | B15: CA-2013-121755 | C15: =YEAR(Data!$D27) -> 2013 | D15: 41290 | E15: 41294 | F15: Second Class | G15: EH-13945 | H15: Consumer | I15: United States | J15: Los Angeles | K15: California | L15: 90049 | M15: West | N15: OFF-BI-10001634 | O15: Office Supplies | P15: Binders | Q15: 11.648 | R15: 2 | S15: 0.2 | T15: 4.2224
A16: Tracy Blumstein | B16: US-2012-150630 | C16: =YEAR(Data!$D29) -> 2012 | D16: 41169 | E16: 41173 | F16: Standard Class | G16: TB-21520 | H16: Consumer | I16: United States | J16: Philadelphia | K16: Pennsylvania | L16: 19140 | M16: East | N16: FUR-BO-10004834 | O16: Furniture | P16: Bookcases | Q16: 3083.43 | R16: 7 | S16: 0.5 | T16: -1665.0522
A17: Matt Abelman | B17: CA-2014-107727 | C17: =YEAR(Data!$D36) -> 2014 | D17: 41932 | E17: 41936 | F17: Second Class | G17: MA-17560 | H17: Home Office | I17: United States | J17: Houston | K17: Texas | L17: 77095 | M17: Central | N17: OFF-PA-10000249 | O17: Office Supplies | P17: Paper | Q17: 29.472 | R17: 3 | S17: 0.2 | T17: 9.9468
A18: Gene Hale | B18: CA-2013-117590 | C18: =YEAR(Data!$D37) -> 2011 | D18: 41617 | E18: 41619 | F18: First Class | G18: GH-14485 | H18: Corporate | I18: United States | J18: Richardson | K18: Texas | L18: 75080 | M18: Central | N18: TEC-PH-10004977 | O18: Technology | P18: Phones | Q18: 1097.544 | R18: 7 | S18: 0.2 | T18: 123.4737
A19: Steve Nguyen | B19: CA-2012-117415 | C19: =YEAR(Data!$D39) -> 2011 | D19: 41270 | E19: 41274 | F19: Standard Class | G19: SN-20710 | H19: Home Office | I19: United States | J19: Houston | K19: Texas | L19: 77041 | M19: Central | N19: OFF-EN-10002986 | O19: Office Supplies | P19: Envelopes | Q19: 113.328 | R19: 9 | S19: 0.2 | T19: 35.415
A20: Linda Cazamias | B20: CA-2014-120999 | C20: =YEAR(Data!$D43) -> 2014 | D20: 41893 | E20: 41898 | F20: Standard Class | G20: LC-16930 | H20: Corporate | I20: United States | J20: Naperville | K20: Illinois | L20: 60540 | M20: Central | N20: TEC-PH-10004093 | O20: Technology | P20: Phones | Q20: 147.168 | R20: 4 | S20: 0.2 | T20: 16.5564
A21: Ruben Ausman | B21: CA-2013-101343 | C21: =YEAR(Data!$D44) -> 2013 | D21: 41473 | E21: 41478 | F21: Standard Class | G21: RA-19885 | H21: Corporate | I21: United States | J21: Los Angeles | K21: California | L21: 90049 | M21: West | N21: OFF-ST-10003479 | O21: Office Supplies | P21: Storage | Q21: 77.88 | R21: 2 | S21: 0 | T21: 3.894
A22: Erin Smith | B22: CA-2014-139619 | C22: =YEAR(Data!$D45) -> 2013 | D22: 41902 | E22: 41906 | F22: Standard Class | G22: ES-14080 | H22: Corporate | I22: United States | J22: Melbourne | K22: Florida | L22: 32935 | M22: South | N22: OFF-ST-10003282 | O22: Office Supplies | P22: Storage | Q22: 95.616 | R22: 2 | S22: 0.2 | T22: 9.5616
A23: Odella Nelson | B23: CA-2013-118255 | C23: =YEAR(Data!$D46) -> 2012 | D23: 41345 | E23: 41347 | F23: First Class | G23: ON-18715 | H23: Corporate | I23: United States | J23: Eagan | K23: Minnesota | L23: 55122 | M23: Central | N23: TEC-AC-10000171 | O23: Technology | P23: Accessories | Q23: 45.98 | R23: 2 | S23: 0 | T23: 19.7714
A24: Patrick O'Donnell | B24: CA-2011-146703 | C24: =YEAR(Data!$D48) -> 2014 | D24: 40836 | E24: 40841 | F24: Second Class | G24: PO-18865 | H24: Consumer | I24: United States | J24: Westland | K24: Michigan | L24: 48185 | M24: Central | N24: OFF-ST-10001713 | O24: Office Supplies | P24: Storage | Q24: 211.96 | R24: 4 | S24: 0 | T24: 8.4784
A25: Lena Hernandez | B25: CA-2013-169194 | C25: =YEAR(Data!$D49) -> 2014 | D25: 41446 | E25: 41451 | F25: Standard Class | G25: LH-16900 | H25: Consumer | I25: United States | J25: Dover | K25: Delaware | L25: 19901 | M25: East | N25: TEC-AC-10002167 | O25: Technology | P25: Accessories | Q25: 45 | R25: 3 | S25: 0 | T25: 4.95
A26: Darren Powers | B26: CA-2012-115742 | C26: =YEAR(Data!$D51) -> 2013 | D26: 41017 | E26: 41021 | F26: Standard Class | G26: DP-13000 | H26: Consumer | I26: United States | J26: New Albany | K26: Indiana | L26: 47150 | M26: Central | N26: OFF-BI-10004410 | O26: Office Supplies | P26: Binders | Q26: 38.22 | R26: 6 | S26: 0 | T26: 17.9634
A27: Janet Molinari | B27: CA-2013-105816 | C27: =YEAR(Data!$D55) -> 2012 | D27: 41620 | E27: 41626 | F27: Standard Class | G27: JM-15265 | H27: Corporate | I27: United States | J27: New York City | K27: New York | L27: 10024 | M27: East | N27: OFF-FA-10000304 | O27: Office Supplies | P27: Fasteners | Q27: 15.26 | R27: 7 | S27: 0 | T27: 6.2566
A28: Ted Butterfield | B28: CA-2013-111682 | C28: =YEAR(Data!$D57) -> 2013 | D28: 41443 | E28: 41444 | F28: First Class | G28: TB-21055 | H28: Consumer | I28: United States | J28: Troy | K28: New York | L28: 12180 | M28: East | N28: OFF-ST-10000604 | O28: Office Supplies | P28: Storage | Q28: 208.56 | R28: 6 | S28: 0 | T28: 52.14
A29: Kunst Miller | B29: CA-2012-135545 | C29: =YEAR(Data!$D64) -> 2014 | D29: 41237 | E29: 41243 | F29: Standard Class | G29: KM-16720 | H29: Consumer | I29: United States | J29: Los Angeles | K29: California | L29: 90004 | M29: West | N29: TEC-AC-10004633 | O29: Technology | P29: Accessories | Q29: 13.98 | R29: 2 | S29: 0 | T29: 6.1512
A30: Paul Stevenson | B30: US-2012-164175 | C30: =YEAR(Data!$D68) -> 2013 | D30: 41029 | E30: 41034 | F30: Standard Class | G30: PS-18970 | H30: Home Office | I30: United States | J30: Chicago | K30: Illinois | L30: 60610 | M30: Central | N30: FUR-CH-10001146 | O30: Furniture | P30: Chairs | Q30: 213.115 | R30: 5 | S30: 0.3 | T30: -15.2225
A31: Brendan Sweed | B31: CA-2011-106376 | C31: =YEAR(Data!$D69) -> 2014 | D31: 40882 | E31: 40887 | F31: Standard Class | G31: BS-11590 | H31: Corporate | I31: United States | J31: Gilbert | K31: Arizona | L31: 85234 | M31: West | N31: OFF-AR-10002671 | O31: Office Supplies | P31: Art | Q31: 1113.024 | R31: 8 | S31: 0.2 | T31: 111.3024
A32: Karen Daniels | B32: CA-2013-119823 | C32: =YEAR(Data!$D71) -> 2012 | D32: 41430 | E32: 41432 | F32: First Class | G32: KD-16270 | H32: Consumer | I32: United States | J32: Springfield | K32: Virginia | L32: 22153 | M32: South | N32: OFF-PA-10000482 | O32: Office Supplies | P32: Paper | Q32: 75.88 | R32: 2 | S32: 0 | T32: 35.6636
A33: Henry MacAllister | B33: CA-2013-106075 | C33: =YEAR(Data!$D72) -> 2011 | D33: 41536 | E33: 41541 | F33: Standard Class | G33: HM-14980 | H33: Consumer | I33: United States | J33: New York City | K33: New York | L33: 10009 | M33: East | N33: OFF-BI-10004654 | O33: Office Supplies | P33: Binders | Q33: 4.616 | R33: 1 | S33: 0.2 | T33: 1.731
A34: Tracy Blumstein | B34: CA-2014-114440 | C34: =YEAR(Data!$D73) -> 2013 | D34: 41897 | E34: 41900 | F34: Second Class | G34: TB-21520 | H34: Consumer | I34: United States | J34: Jackson | K34: Michigan | L34: 49201 | M34: Central | N34: OFF-PA-10004675 | O34: Office Supplies | P34: Paper | Q34: 19.05 | R34: 3 | S34: 0 | T34: 8.763
A35: Joel Eaton | B35: US-2012-134026 | C35: =YEAR(Data!$D74) -> 2013 | D35: 41025 | E35: 41031 | F35: Standard Class | G35: JE-15745 | H35: Consumer | I35: United States | J35: Memphis | K35: Tennessee | L35: 38109 | M35: South | N35: FUR-CH-10000513 | O35: Furniture | P35: Chairs | Q35: 831.936 | R35: 8 | S35: 0.2 | T35: -114.3912
A36: Ken Brennan | B36: US-2014-118038 | C36: =YEAR(Data!$D77) -> 2011 | D36: 41983 | E36: 41985 | F36: First Class | G36: KB-16600 | H36: Corporate | I36: United States | J36: Houston | K36: Texas | L36: 77041 | M36: Central | N36: OFF-BI-10004182 | O36: Office Supplies | P36: Binders | Q36: 1.248 | R36: 3 | S36: 0.8 | T36: -1.9344
A37: Joel Eaton | B37: US-2011-147606 | C37: =YEAR(Data!$D80) -> 2012 | D37: 40873 | E37: 40878 | F37: Second Class | G37: JE-15745 | H37: Consumer | I37: United States | J37: Houston | K37: Texas | L37: 77070 | M37: Central | N37: FUR-FU-10003194 | O37: Furniture | P37: Furnishings | Q37: 19.3 | R37: 5 | S37: 0.6 | T37: -14.475
A38: Stewart Carmichael | B38: CA-2013-127208 | C38: =YEAR(Data!$D81) -> 2013 | D38: 41438 | E38: 41441 | F38: First Class | G38: SC-20770 | H38: Corporate | I38: United States | J38: Decatur | K38: Alabama | L38: 35601 | M38: South | N38: OFF-AP-10002118 | O38: Office Supplies | P38: Appliances | Q38: 208.16 | R38: 1 | S38: 0 | T38: 56.2032
A39: Duane Noonan | B39: CA-2011-139451 | C39: =YEAR(Data!$D83) -> 2011 | D39: 40828 | E39: 40832 | F39: Standard Class | G39: DN-13690 | H39: Consumer | I39: United States | J39: San Francisco | K39: California | L39: 94122 | M39: West | N39: OFF-AR-10002053 | O39: Office Supplies | P39: Art | Q39: 14.9 | R39: 5 | S39: 0 | T39: 4.172
A40: Julie Creighton | B40: CA-2012-149734 | C40: =YEAR(Data!$D85) -> 2011 | D40: 41155 | E40: 41160 | F40: Standard Class | G40: JC-16105 | H40: Corporate | I40: United States | J40: Durham | K40: North Carolina | L40: 27707 | M40: South | N40: OFF-EN-10000927 | O40: Office Supplies | P40: Envelopes | Q40: 200.984 | R40: 7 | S40: 0.2 | T40: 62.8075
...

Sheet Combo Chart
A3: Row Labels | B3: Sum of Sales | C3: Sum of Profit
A4: Jan | B4: 95365.938 | C4: 9199.27
A5: Mar | B5: 199252.98 | C5: 26806.574
A6: Apr | B6: 141851.57 | C6: 13437.807
A7: May | B7: 156122.29 | C7: 22308.513
A8: Aug | B8: 159589.45 | C8: 21896.715
A9: Sep | B9: 309770.1 | C9: 37293.192
A10: Oct | B10: 197115.2 | C10: 31469.664
A11: Nov | B11: 349120.07 | C11: 35825.537
A12: Dec | B12: 332177.16 | C12: 43436.134

Sheet Dashboard
R4: ECOMMERCE SALES AND ANALYSIS DASHBOARD

Sheet Doughnut Chart
A3: Row Labels | B3: Sum of Sales
A4: Furniture | B4: 0.32300171
A5: Office Supplies | B5: 0.31301008
A6: Technology | B6: 0.36398821
A7: Grand Total | B7: 1

Sheet Map Chart
A3: Row Labels | B3: Sum of Sales | D3: State | E3: Sales
A4: Alabama | B4: 19510.64 | D4: =A4 -> Alabama | E4: =GETPIVOTDATA("Sales",$A$3,"State",A4) -> 19510.64
A5: Arizona | B5: 35282.001 | D5: =A5 -> Arizona | E5: =GETPIVOTDATA("Sales",$A$3,"State",A5) -> 35282.001
A6: California | B6: 457687.63 | D6: =A6 -> California | E6: =GETPIVOTDATA("Sales",$A$3,"State",A6) -> 457687.63
A7: Colorado | B7: 32108.118 | D7: =A7 -> Colorado | E7: =GETPIVOTDATA("Sales",$A$3,"State",A7) -> 32108.118
A8: Idaho | B8: 4382.486 | D8: =A8 -> Idaho | E8: =GETPIVOTDATA("Sales",$A$3,"State",A8) -> 4382.486
A9: Indiana | B9: 53555.36 | D9: =A9 -> Indiana | E9: =GETPIVOTDATA("Sales",$A$3,"State",A9) -> 53555.36
A10: Kansas | B10: 2914.31 | D10: =A10 -> Kansas | E10: =GETPIVOTDATA("Sales",$A$3,"State",A10) -> 2914.31
A11: Kentucky | B11: 36591.75 | D11: =A11 -> Kentucky | E11: =GETPIVOTDATA("Sales",$A$3,"State",A11) -> 36591.75
A12: Michigan | B12: 76269.614 | D12: =A12 -> Michigan | E12: =GETPIVOTDATA("Sales",$A$3,"State",A12) -> 76269.614
A13: Minnesota | B13: 29863.15 | D13: =A13 -> Minnesota | E13: =GETPIVOTDATA("Sales",$A$3,"State",A13) -> 29863.15
A14: New Hampshire | B14: 7292.524 | D14: =A14 -> New Hampshire | E14: =GETPIVOTDATA("Sales",$A$3,"State",A14) -> 7292.524
A15: New York | B15: 310876.27 | D15: =A15 -> New York | E15: =GETPIVOTDATA("Sales",$A$3,"State",A15) -> 310876.27
... A17: Grand Total | B17: 1121937 | D17: =A17 -> Grand Total | E17: =GETPIVOTDATA("Sales",$A$3,"State",A17) -> #REF!
D18: =A18 -> 0 | E18: =GETPIVOTDATA("Sales",$A$3,"State",A18) -> #REF!
D19: =A19 -> 0 | E19: =GETPIVOTDATA("Sales",$A$3,"State",A19) -> #REF!
D20: =A20 -> 0 | E20: =GETPIVOTDATA("Sales",$A$3,"State",A20) -> #REF!
D21: =A21 -> 0 | E21: =GETPIVOTDATA("Sales",$A$3,"State",A21) -> #REF!
D22: =A22 -> 0 | E22: =GETPIVOTDATA("Sales",$A$3,"State",A22) -> #REF!
D23: =A23 -> 0 | E23: =GETPIVOTDATA("Sales",$A$3,"State",A23) -> #REF!
D24: =A24 -> 0 | E24: =GETPIVOTDATA("Sales",$A$3,"State",A24) -> #REF!
D25: =A25 -> 0 | E25: =GETPIVOTDATA("Sales",$A$3,"State",A25) -> #REF!
D26: =A26 -> 0 | E26: =GETPIVOTDATA("Sales",$A$3,"State",A26) -> #REF!
D27: =A27 -> 0 | E27: =GETPIVOTDATA("Sales",$A$3,"State",A27) -> #REF!
D28: =A28 -> 0 | E28: =GETPIVOTDATA("Sales",$A$3,"State",A28) -> #REF!
D29: =A29 -> 0 | E29: =GETPIVOTDATA("Sales",$A$3,"State",A29) -> #REF!
... D52: =A52 -> 0 | E52: =GETPIVOTDATA("Sales",$A$3,"State",A52) -> #REF!
D53: =A53 -> 0 | E53: =GETPIVOTDATA("Sales",$A$3) -> 1121937

Sheet Bar Chart
A3: Row Labels | B3: Sum of Sales
A4: Envelopes | B4: 16476.402
A5: Art | B5: 27118.792
A6: Appliances | B6: 107532.16
A7: Copiers | B7: 149528.03
A8: Binders | B8: 203412.73
A9: Chairs | B9: 328449.1
A10: Grand Total | B10: 832517.22

Sheet KPI
A3: Row Labels | B3: Sum of Sales | D3: Row Labels | E3: Sum of Profit | G3: Row Labels | H3: Sum of Quantity | J3: Row Labels | K3: Count of Order ID | M3: Row Labels | N3: Sum of Profit Margin
A4: Jan | B4: 95365.938 | D4: Jan | E4: 9199.27 | G4: Mar | H4: 2491 | J4: Feb | K4: 301 | M4: Mar | N4: 0.13453537
A5: Feb | B5: 60172.649 | D5: Feb | E5: 10288.899 | G5: Apr | H5: 2441 | J5: Mar | K5: 680 | M5: Apr | N5: 0.094731465
A6: Grand Total | B6: 155538.59 | D6: Grand Total | E6: 19488.169 | G6: Grand Total | H6: 4932 | J6: Grand Total | K6: 981 | M6: Grand Total | N6: 0.11798254
